{"uuid": "6b49af39-3e71-4d6d-ba59-65657e417bca", "children": ["fd6b2e0c-ed71-4786-8aa8-154203138a69", "62e2329e-97f9-41f1-93f4-5f2984cfd3e6", "e032bbaf-60d0-4b60-8109-6eb7722b3232", "7f9704e5-07dc-447e-a0b5-b4bc933175b2", "15f70600-cb56-4443-a5c1-cddffb61ccc0", "0742231f-b549-479e-b2c2-31573a9c4061", "bee47ee2-74d9-443c-8fc2-ec1d38687c7a", "1f995be2-f5aa-494e-9563-6daf3f1e11c6", "8b3a3338-900c-4f16-8249-0523a8318e8d", "49229609-66c6-4472-84cf-f54575c3658a"], "befores": [{"name": "_Class__pytest_setup_class", "status": "broken", "statusDetails": {"message": "pymysql.err.InternalError: (1049, \"Unknown database 't_stock_search'\")\n", "trace": "  File \"C:\\Users\\ASUS\\AppData\\Local\\Programs\\Python\\Python38\\lib\\site-packages\\pluggy\\callers.py\", line 187, in _multicall\n    res = hook_impl.function(*args)\n  File \"C:\\Users\\ASUS\\AppData\\Local\\Programs\\Python\\Python38\\lib\\site-packages\\_pytest\\fixtures.py\", line 964, in pytest_fixture_setup\n    result = call_fixture_func(fixturefunc, request, kwargs)\n  File \"C:\\Users\\ASUS\\AppData\\Local\\Programs\\Python\\Python38\\lib\\site-packages\\_pytest\\fixtures.py\", line 788, in call_fixture_func\n    res = next(it)\n  File \"C:\\Users\\ASUS\\AppData\\Local\\Programs\\Python\\Python38\\lib\\site-packages\\_pytest\\python.py\", line 701, in xunit_setup_class_fixture\n    _call_with_optional_argument(func, self.obj)\n  File \"C:\\Users\\ASUS\\AppData\\Local\\Programs\\Python\\Python38\\lib\\site-packages\\_pytest\\python.py\", line 632, in _call_with_optional_argument\n    func(arg)\n  File \"D:\\zrapiautotestv1.0\\TestCase\\StockQuotation\\AstockRelevance\\test_Astcok_F10financial_report.py\", line 15, in setup_class\n    stock_code = str(q.show_sql(\"select code from t_stock_search where `ts`= 'HK';\"))\n  File \"D:\\zrapiautotestv1.0\\Common\\show_sql.py\", line 56, in show_sql\n    raise e\n  File \"D:\\zrapiautotestv1.0\\Common\\show_sql.py\", line 52, in show_sql\n    cursor = self.get_newCursor()\n  File \"D:\\zrapiautotestv1.0\\Common\\show_sql.py\", line 33, in get_newCursor\n    self._cursor = self.get_connect_sql().cursor()\n  File \"D:\\zrapiautotestv1.0\\Common\\show_sql.py\", line 27, in get_connect_sql\n    self._conn = pymysql.connect(self.address, self.user, self.password, self.database)\n  File \"C:\\Users\\ASUS\\AppData\\Local\\Programs\\Python\\Python38\\lib\\site-packages\\pymysql\\__init__.py\", line 94, in Connect\n    return Connection(*args, **kwargs)\n  File \"C:\\Users\\ASUS\\AppData\\Local\\Programs\\Python\\Python38\\lib\\site-packages\\pymysql\\connections.py\", line 325, in __init__\n    self.connect()\n  File \"C:\\Users\\ASUS\\AppData\\Local\\Programs\\Python\\Python38\\lib\\site-packages\\pymysql\\connections.py\", line 599, in connect\n    self._request_authentication()\n  File \"C:\\Users\\ASUS\\AppData\\Local\\Programs\\Python\\Python38\\lib\\site-packages\\pymysql\\connections.py\", line 861, in _request_authentication\n    auth_packet = self._read_packet()\n  File \"C:\\Users\\ASUS\\AppData\\Local\\Programs\\Python\\Python38\\lib\\site-packages\\pymysql\\connections.py\", line 684, in _read_packet\n    packet.check_error()\n  File \"C:\\Users\\ASUS\\AppData\\Local\\Programs\\Python\\Python38\\lib\\site-packages\\pymysql\\protocol.py\", line 220, in check_error\n    err.raise_mysql_exception(self._data)\n  File \"C:\\Users\\ASUS\\AppData\\Local\\Programs\\Python\\Python38\\lib\\site-packages\\pymysql\\err.py\", line 109, in raise_mysql_exception\n    raise errorclass(errno, errval)\n"}, "start": 1595899222801, "stop": 1595899222836}], "start": 1595899222801, "stop": 1595899223613}