{"uuid": "fe81a3ad-ed5b-4b6a-aade-2d15cd33904e", "children": ["f9d974fb-cff8-4c89-bcb6-64671e3e6b2d", "b6d2c166-57e3-4c32-a7e3-ba111473e703", "dbb23ceb-370f-4d37-884c-b0c45b67dd44", "c9f04912-72e4-47d0-b298-5db6545e41d1", "6bc48a59-5ade-40ba-9784-5603e807a5e6", "72590e06-3a60-4254-8d22-6408498a67a5", "8dcda69d-9039-488f-8f25-80c8bfd79f72", "a685c9ad-6a1c-4ea4-945a-7126a789482d", "e9d6fafa-235f-473e-8710-b0cc16ae3ba1", "208a5c58-45f6-4e06-9876-991af4f32402"], "befores": [{"name": "_Class__pytest_setup_class", "status": "broken", "statusDetails": {"message": "pymysql.err.InternalError: (1049, \"Unknown database 't_stock_search'\")\n", "trace": "  File \"C:\\Users\\ASUS\\AppData\\Local\\Programs\\Python\\Python38\\lib\\site-packages\\pluggy\\callers.py\", line 187, in _multicall\n    res = hook_impl.function(*args)\n  File \"C:\\Users\\ASUS\\AppData\\Local\\Programs\\Python\\Python38\\lib\\site-packages\\_pytest\\fixtures.py\", line 964, in pytest_fixture_setup\n    result = call_fixture_func(fixturefunc, request, kwargs)\n  File \"C:\\Users\\ASUS\\AppData\\Local\\Programs\\Python\\Python38\\lib\\site-packages\\_pytest\\fixtures.py\", line 788, in call_fixture_func\n    res = next(it)\n  File \"C:\\Users\\ASUS\\AppData\\Local\\Programs\\Python\\Python38\\lib\\site-packages\\_pytest\\python.py\", line 701, in xunit_setup_class_fixture\n    _call_with_optional_argument(func, self.obj)\n  File \"C:\\Users\\ASUS\\AppData\\Local\\Programs\\Python\\Python38\\lib\\site-packages\\_pytest\\python.py\", line 632, in _call_with_optional_argument\n    func(arg)\n  File \"D:\\zrapiautotestv1.0\\TestCase\\StockQuotation\\AstockRelevance\\test_Astcok_F10financial_report.py\", line 15, in setup_class\n    stock_code = str(q.show_sql(\"select code from t_stock_search where `ts`= 'HK';\"))\n  File \"D:\\zrapiautotestv1.0\\Common\\show_sql.py\", line 56, in show_sql\n    raise e\n  File \"D:\\zrapiautotestv1.0\\Common\\show_sql.py\", line 52, in show_sql\n    cursor = self.get_newCursor()\n  File \"D:\\zrapiautotestv1.0\\Common\\show_sql.py\", line 33, in get_newCursor\n    self._cursor = self.get_connect_sql().cursor()\n  File \"D:\\zrapiautotestv1.0\\Common\\show_sql.py\", line 27, in get_connect_sql\n    self._conn = pymysql.connect(self.address, self.user, self.password, self.database)\n  File \"C:\\Users\\ASUS\\AppData\\Local\\Programs\\Python\\Python38\\lib\\site-packages\\pymysql\\__init__.py\", line 94, in Connect\n    return Connection(*args, **kwargs)\n  File \"C:\\Users\\ASUS\\AppData\\Local\\Programs\\Python\\Python38\\lib\\site-packages\\pymysql\\connections.py\", line 325, in __init__\n    self.connect()\n  File \"C:\\Users\\ASUS\\AppData\\Local\\Programs\\Python\\Python38\\lib\\site-packages\\pymysql\\connections.py\", line 599, in connect\n    self._request_authentication()\n  File \"C:\\Users\\ASUS\\AppData\\Local\\Programs\\Python\\Python38\\lib\\site-packages\\pymysql\\connections.py\", line 861, in _request_authentication\n    auth_packet = self._read_packet()\n  File \"C:\\Users\\ASUS\\AppData\\Local\\Programs\\Python\\Python38\\lib\\site-packages\\pymysql\\connections.py\", line 684, in _read_packet\n    packet.check_error()\n  File \"C:\\Users\\ASUS\\AppData\\Local\\Programs\\Python\\Python38\\lib\\site-packages\\pymysql\\protocol.py\", line 220, in check_error\n    err.raise_mysql_exception(self._data)\n  File \"C:\\Users\\ASUS\\AppData\\Local\\Programs\\Python\\Python38\\lib\\site-packages\\pymysql\\err.py\", line 109, in raise_mysql_exception\n    raise errorclass(errno, errval)\n"}, "start": 1595899136030, "stop": 1595899180991}], "start": 1595899136030, "stop": 1595899183379}