{"uuid": "2df902e7-ce95-432c-bc33-2dac63a4f00d", "children": ["2abf7d23-7e2b-4e04-aa33-f73468ea88d2", "f434fb86-4260-4af9-be6c-516557b42290", "d7818214-8c48-4205-93c7-9bf7c0eca543", "c4aacab3-470e-42e7-8d37-705df8472f64", "13976fc7-5f68-4635-9905-5a6a90474b2c", "ce0cc708-d1d2-417a-a97b-ee0569d9f619", "f90ea523-06c8-4e3b-ae78-431628a15a6c", "1dd311f9-fdeb-45b0-8180-e4f8f2417ae5", "cf5f5e2b-11cc-448e-93bf-ffc405044819", "aecf6eff-9296-401b-b81e-33fa5b0a4ffb"], "befores": [{"name": "_Class__pytest_setup_class", "status": "broken", "statusDetails": {"message": "pymysql.err.InternalError: (1049, \"Unknown database 't_stock_search'\")\n", "trace": "  File \"C:\\Users\\ASUS\\AppData\\Local\\Programs\\Python\\Python38\\lib\\site-packages\\pluggy\\callers.py\", line 187, in _multicall\n    res = hook_impl.function(*args)\n  File \"C:\\Users\\ASUS\\AppData\\Local\\Programs\\Python\\Python38\\lib\\site-packages\\_pytest\\fixtures.py\", line 964, in pytest_fixture_setup\n    result = call_fixture_func(fixturefunc, request, kwargs)\n  File \"C:\\Users\\ASUS\\AppData\\Local\\Programs\\Python\\Python38\\lib\\site-packages\\_pytest\\fixtures.py\", line 788, in call_fixture_func\n    res = next(it)\n  File \"C:\\Users\\ASUS\\AppData\\Local\\Programs\\Python\\Python38\\lib\\site-packages\\_pytest\\python.py\", line 701, in xunit_setup_class_fixture\n    _call_with_optional_argument(func, self.obj)\n  File \"C:\\Users\\ASUS\\AppData\\Local\\Programs\\Python\\Python38\\lib\\site-packages\\_pytest\\python.py\", line 632, in _call_with_optional_argument\n    func(arg)\n  File \"D:\\zrapiautotestv1.0\\TestCase\\StockQuotation\\AstockRelevance\\test_Astcok_F10financial_report.py\", line 15, in setup_class\n    stock_code = str(q.show_sql(\"select code from t_stock_search where `ts`= 'A';\"))\n  File \"D:\\zrapiautotestv1.0\\Common\\show_sql.py\", line 56, in show_sql\n    raise e\n  File \"D:\\zrapiautotestv1.0\\Common\\show_sql.py\", line 52, in show_sql\n    cursor = self.get_newCursor()\n  File \"D:\\zrapiautotestv1.0\\Common\\show_sql.py\", line 33, in get_newCursor\n    self._cursor = self.get_connect_sql().cursor()\n  File \"D:\\zrapiautotestv1.0\\Common\\show_sql.py\", line 27, in get_connect_sql\n    self._conn = pymysql.connect(self.address, self.user, self.password, self.database)\n  File \"C:\\Users\\ASUS\\AppData\\Local\\Programs\\Python\\Python38\\lib\\site-packages\\pymysql\\__init__.py\", line 94, in Connect\n    return Connection(*args, **kwargs)\n  File \"C:\\Users\\ASUS\\AppData\\Local\\Programs\\Python\\Python38\\lib\\site-packages\\pymysql\\connections.py\", line 325, in __init__\n    self.connect()\n  File \"C:\\Users\\ASUS\\AppData\\Local\\Programs\\Python\\Python38\\lib\\site-packages\\pymysql\\connections.py\", line 599, in connect\n    self._request_authentication()\n  File \"C:\\Users\\ASUS\\AppData\\Local\\Programs\\Python\\Python38\\lib\\site-packages\\pymysql\\connections.py\", line 861, in _request_authentication\n    auth_packet = self._read_packet()\n  File \"C:\\Users\\ASUS\\AppData\\Local\\Programs\\Python\\Python38\\lib\\site-packages\\pymysql\\connections.py\", line 684, in _read_packet\n    packet.check_error()\n  File \"C:\\Users\\ASUS\\AppData\\Local\\Programs\\Python\\Python38\\lib\\site-packages\\pymysql\\protocol.py\", line 220, in check_error\n    err.raise_mysql_exception(self._data)\n  File \"C:\\Users\\ASUS\\AppData\\Local\\Programs\\Python\\Python38\\lib\\site-packages\\pymysql\\err.py\", line 109, in raise_mysql_exception\n    raise errorclass(errno, errval)\n"}, "start": 1595899101026, "stop": 1595899101060}], "start": 1595899101026, "stop": 1595899101842}