{"uuid": "98ab182c-55ba-49e4-8084-851d4bfb7897", "children": ["8a2318ca-1437-43f7-916d-ca60f7d9b454", "b057beee-934f-4e5f-95e2-705a89c30273", "8b7285fd-b047-4bdf-8819-67c5079f4871", "d071e85a-4090-4ae4-9e2e-9cd88f6d3415", "41d74a02-31d5-42d4-a4d6-8c2557c3c243", "dd6ec2e2-7f3c-4150-a615-85f9a9a756c2", "21eb09ed-e9b5-4c47-be06-818a7e01c565", "a0025dbb-12a2-4d5e-b306-ef617c21108e", "ca15276e-7cd8-41ac-b5de-d076185fb6b0", "7daab3e5-503e-4b96-a76d-f8c6871f4f28"], "befores": [{"name": "_Class__pytest_setup_class", "status": "broken", "statusDetails": {"message": "pymysql.err.InternalError: (1049, \"Unknown database 't_stock_search'\")\n", "trace": "  File \"C:\\Users\\ASUS\\AppData\\Local\\Programs\\Python\\Python38\\lib\\site-packages\\pluggy\\callers.py\", line 187, in _multicall\n    res = hook_impl.function(*args)\n  File \"C:\\Users\\ASUS\\AppData\\Local\\Programs\\Python\\Python38\\lib\\site-packages\\_pytest\\fixtures.py\", line 964, in pytest_fixture_setup\n    result = call_fixture_func(fixturefunc, request, kwargs)\n  File \"C:\\Users\\ASUS\\AppData\\Local\\Programs\\Python\\Python38\\lib\\site-packages\\_pytest\\fixtures.py\", line 788, in call_fixture_func\n    res = next(it)\n  File \"C:\\Users\\ASUS\\AppData\\Local\\Programs\\Python\\Python38\\lib\\site-packages\\_pytest\\python.py\", line 701, in xunit_setup_class_fixture\n    _call_with_optional_argument(func, self.obj)\n  File \"C:\\Users\\ASUS\\AppData\\Local\\Programs\\Python\\Python38\\lib\\site-packages\\_pytest\\python.py\", line 632, in _call_with_optional_argument\n    func(arg)\n  File \"D:\\zrapiautotestv1.0\\TestCase\\StockQuotation\\AstockRelevance\\test_Astcok_F10financial_report.py\", line 15, in setup_class\n    stock_code = str(q.show_sql(\"select code from t_stock_search where `ts`= 'A';\"))\n  File \"D:\\zrapiautotestv1.0\\Common\\show_sql.py\", line 56, in show_sql\n    raise e\n  File \"D:\\zrapiautotestv1.0\\Common\\show_sql.py\", line 52, in show_sql\n    cursor = self.get_newCursor()\n  File \"D:\\zrapiautotestv1.0\\Common\\show_sql.py\", line 33, in get_newCursor\n    self._cursor = self.get_connect_sql().cursor()\n  File \"D:\\zrapiautotestv1.0\\Common\\show_sql.py\", line 27, in get_connect_sql\n    self._conn = pymysql.connect(self.address, self.user, self.password, self.database)\n  File \"C:\\Users\\ASUS\\AppData\\Local\\Programs\\Python\\Python38\\lib\\site-packages\\pymysql\\__init__.py\", line 94, in Connect\n    return Connection(*args, **kwargs)\n  File \"C:\\Users\\ASUS\\AppData\\Local\\Programs\\Python\\Python38\\lib\\site-packages\\pymysql\\connections.py\", line 325, in __init__\n    self.connect()\n  File \"C:\\Users\\ASUS\\AppData\\Local\\Programs\\Python\\Python38\\lib\\site-packages\\pymysql\\connections.py\", line 599, in connect\n    self._request_authentication()\n  File \"C:\\Users\\ASUS\\AppData\\Local\\Programs\\Python\\Python38\\lib\\site-packages\\pymysql\\connections.py\", line 861, in _request_authentication\n    auth_packet = self._read_packet()\n  File \"C:\\Users\\ASUS\\AppData\\Local\\Programs\\Python\\Python38\\lib\\site-packages\\pymysql\\connections.py\", line 684, in _read_packet\n    packet.check_error()\n  File \"C:\\Users\\ASUS\\AppData\\Local\\Programs\\Python\\Python38\\lib\\site-packages\\pymysql\\protocol.py\", line 220, in check_error\n    err.raise_mysql_exception(self._data)\n  File \"C:\\Users\\ASUS\\AppData\\Local\\Programs\\Python\\Python38\\lib\\site-packages\\pymysql\\err.py\", line 109, in raise_mysql_exception\n    raise errorclass(errno, errval)\n"}, "start": 1595899075104, "stop": 1595899075139}], "start": 1595899075104, "stop": 1595899075965}